[03/Mar/2019 21:38:54] ERROR [django.request:228] Internal Server Error: /home/booking_confirmed
Traceback (most recent call last):
  File "/Library/Frameworks/Python.framework/Versions/3.6/lib/python3.6/site-packages/django/core/handlers/exception.py", line 34, in inner
    response = get_response(request)
  File "/Library/Frameworks/Python.framework/Versions/3.6/lib/python3.6/site-packages/django/core/handlers/base.py", line 156, in _get_response
    response = self.process_exception_by_middleware(e, request)
  File "/Library/Frameworks/Python.framework/Versions/3.6/lib/python3.6/site-packages/django/core/handlers/base.py", line 154, in _get_response
    response = response.render()
  File "/Library/Frameworks/Python.framework/Versions/3.6/lib/python3.6/site-packages/django/template/response.py", line 106, in render
    self.content = self.rendered_content
  File "/Library/Frameworks/Python.framework/Versions/3.6/lib/python3.6/site-packages/django/template/response.py", line 81, in rendered_content
    template = self.resolve_template(self.template_name)
  File "/Library/Frameworks/Python.framework/Versions/3.6/lib/python3.6/site-packages/django/template/response.py", line 63, in resolve_template
    return select_template(template, using=self.using)
  File "/Library/Frameworks/Python.framework/Versions/3.6/lib/python3.6/site-packages/django/template/loader.py", line 47, in select_template
    raise TemplateDoesNotExist(', '.join(template_name_list), chain=chain)
django.template.exceptions.TemplateDoesNotExist: booking-confirmed.html
[03/Mar/2019 21:38:54] ERROR [django.server:154] "GET /home/booking_confirmed HTTP/1.1" 500 77916
[03/Mar/2019 21:38:58] ERROR [django.request:228] Internal Server Error: /home/booking_confirmed
Traceback (most recent call last):
  File "/Library/Frameworks/Python.framework/Versions/3.6/lib/python3.6/site-packages/django/core/handlers/exception.py", line 34, in inner
    response = get_response(request)
  File "/Library/Frameworks/Python.framework/Versions/3.6/lib/python3.6/site-packages/django/core/handlers/base.py", line 156, in _get_response
    response = self.process_exception_by_middleware(e, request)
  File "/Library/Frameworks/Python.framework/Versions/3.6/lib/python3.6/site-packages/django/core/handlers/base.py", line 154, in _get_response
    response = response.render()
  File "/Library/Frameworks/Python.framework/Versions/3.6/lib/python3.6/site-packages/django/template/response.py", line 106, in render
    self.content = self.rendered_content
  File "/Library/Frameworks/Python.framework/Versions/3.6/lib/python3.6/site-packages/django/template/response.py", line 81, in rendered_content
    template = self.resolve_template(self.template_name)
  File "/Library/Frameworks/Python.framework/Versions/3.6/lib/python3.6/site-packages/django/template/response.py", line 63, in resolve_template
    return select_template(template, using=self.using)
  File "/Library/Frameworks/Python.framework/Versions/3.6/lib/python3.6/site-packages/django/template/loader.py", line 47, in select_template
    raise TemplateDoesNotExist(', '.join(template_name_list), chain=chain)
django.template.exceptions.TemplateDoesNotExist: booking-confirmed.html
[03/Mar/2019 21:38:58] ERROR [django.server:154] "GET /home/booking_confirmed HTTP/1.1" 500 77939
[03/Mar/2019 21:39:24] ERROR [django.request:228] Internal Server Error: /home/booking_confirmed
Traceback (most recent call last):
  File "/Library/Frameworks/Python.framework/Versions/3.6/lib/python3.6/site-packages/django/core/handlers/exception.py", line 34, in inner
    response = get_response(request)
  File "/Library/Frameworks/Python.framework/Versions/3.6/lib/python3.6/site-packages/django/core/handlers/base.py", line 156, in _get_response
    response = self.process_exception_by_middleware(e, request)
  File "/Library/Frameworks/Python.framework/Versions/3.6/lib/python3.6/site-packages/django/core/handlers/base.py", line 154, in _get_response
    response = response.render()
  File "/Library/Frameworks/Python.framework/Versions/3.6/lib/python3.6/site-packages/django/template/response.py", line 106, in render
    self.content = self.rendered_content
  File "/Library/Frameworks/Python.framework/Versions/3.6/lib/python3.6/site-packages/django/template/response.py", line 81, in rendered_content
    template = self.resolve_template(self.template_name)
  File "/Library/Frameworks/Python.framework/Versions/3.6/lib/python3.6/site-packages/django/template/response.py", line 63, in resolve_template
    return select_template(template, using=self.using)
  File "/Library/Frameworks/Python.framework/Versions/3.6/lib/python3.6/site-packages/django/template/loader.py", line 47, in select_template
    raise TemplateDoesNotExist(', '.join(template_name_list), chain=chain)
django.template.exceptions.TemplateDoesNotExist: booking-confirmed.html
[03/Mar/2019 21:39:24] ERROR [django.server:154] "GET /home/booking_confirmed HTTP/1.1" 500 77916
[03/Mar/2019 21:40:43] ERROR [django.request:228] Internal Server Error: /home/booking_confirmed
Traceback (most recent call last):
  File "/Library/Frameworks/Python.framework/Versions/3.6/lib/python3.6/site-packages/django/core/handlers/exception.py", line 34, in inner
    response = get_response(request)
  File "/Library/Frameworks/Python.framework/Versions/3.6/lib/python3.6/site-packages/django/core/handlers/base.py", line 156, in _get_response
    response = self.process_exception_by_middleware(e, request)
  File "/Library/Frameworks/Python.framework/Versions/3.6/lib/python3.6/site-packages/django/core/handlers/base.py", line 154, in _get_response
    response = response.render()
  File "/Library/Frameworks/Python.framework/Versions/3.6/lib/python3.6/site-packages/django/template/response.py", line 106, in render
    self.content = self.rendered_content
  File "/Library/Frameworks/Python.framework/Versions/3.6/lib/python3.6/site-packages/django/template/response.py", line 81, in rendered_content
    template = self.resolve_template(self.template_name)
  File "/Library/Frameworks/Python.framework/Versions/3.6/lib/python3.6/site-packages/django/template/response.py", line 63, in resolve_template
    return select_template(template, using=self.using)
  File "/Library/Frameworks/Python.framework/Versions/3.6/lib/python3.6/site-packages/django/template/loader.py", line 47, in select_template
    raise TemplateDoesNotExist(', '.join(template_name_list), chain=chain)
django.template.exceptions.TemplateDoesNotExist: booking-confirmed.html
[03/Mar/2019 21:40:43] ERROR [django.server:154] "GET /home/booking_confirmed HTTP/1.1" 500 77939
[03/Mar/2019 21:46:14] WARNING [django.request:228] Not Found: /home/booking/
[03/Mar/2019 21:46:14] WARNING [django.server:154] "GET /home/booking/ HTTP/1.1" 404 5663
[03/Mar/2019 21:46:18] WARNING [django.request:228] Not Found: /home/booking/
[03/Mar/2019 21:46:18] WARNING [django.server:154] "GET /home/booking/ HTTP/1.1" 404 5663
[03/Mar/2019 21:46:29] WARNING [django.request:228] Not Found: /home/booking/
[03/Mar/2019 21:46:29] WARNING [django.server:154] "GET /home/booking/ HTTP/1.1" 404 5663
[03/Mar/2019 22:22:57] INFO [home.views:22] User: Casey logged in
[03/Mar/2019 22:38:02] INFO [home.views:22] User: Casey logged in
[03/Mar/2019 22:55:00] INFO [home.views:22] User: super logged in
[03/Mar/2019 22:56:28] INFO [home.views:22] User: Mike logged in
[03/Mar/2019 23:00:31] ERROR [django.request:228] Internal Server Error: /home/profile/2
Traceback (most recent call last):
  File "/Library/Frameworks/Python.framework/Versions/3.6/lib/python3.6/site-packages/django/core/handlers/exception.py", line 34, in inner
    response = get_response(request)
  File "/Library/Frameworks/Python.framework/Versions/3.6/lib/python3.6/site-packages/django/core/handlers/base.py", line 126, in _get_response
    response = self.process_exception_by_middleware(e, request)
  File "/Library/Frameworks/Python.framework/Versions/3.6/lib/python3.6/site-packages/django/core/handlers/base.py", line 124, in _get_response
    response = wrapped_callback(request, *callback_args, **callback_kwargs)
  File "/Library/Frameworks/Python.framework/Versions/3.6/lib/python3.6/site-packages/django/contrib/auth/decorators.py", line 21, in _wrapped_view
    return view_func(request, *args, **kwargs)
  File "/Users/islab/Desktop/MusicApp/musicapp/musicapp_project3/home/views.py", line 94, in profile
    if(book.student == user.student):
  File "/Library/Frameworks/Python.framework/Versions/3.6/lib/python3.6/site-packages/django/db/models/fields/related_descriptors.py", line 414, in __get__
    self.related.get_accessor_name()
django.contrib.auth.models.User.student.RelatedObjectDoesNotExist: User has no student.
[03/Mar/2019 23:00:31] ERROR [django.server:154] "GET /home/profile/2 HTTP/1.1" 500 73606
[03/Mar/2019 23:00:40] ERROR [django.request:228] Internal Server Error: /home/profile/2
Traceback (most recent call last):
  File "/Library/Frameworks/Python.framework/Versions/3.6/lib/python3.6/site-packages/django/core/handlers/exception.py", line 34, in inner
    response = get_response(request)
  File "/Library/Frameworks/Python.framework/Versions/3.6/lib/python3.6/site-packages/django/core/handlers/base.py", line 126, in _get_response
    response = self.process_exception_by_middleware(e, request)
  File "/Library/Frameworks/Python.framework/Versions/3.6/lib/python3.6/site-packages/django/core/handlers/base.py", line 124, in _get_response
    response = wrapped_callback(request, *callback_args, **callback_kwargs)
  File "/Library/Frameworks/Python.framework/Versions/3.6/lib/python3.6/site-packages/django/contrib/auth/decorators.py", line 21, in _wrapped_view
    return view_func(request, *args, **kwargs)
  File "/Users/islab/Desktop/MusicApp/musicapp/musicapp_project3/home/views.py", line 94, in profile
    if(book.student == user.student):
  File "/Library/Frameworks/Python.framework/Versions/3.6/lib/python3.6/site-packages/django/db/models/fields/related_descriptors.py", line 414, in __get__
    self.related.get_accessor_name()
django.contrib.auth.models.User.student.RelatedObjectDoesNotExist: User has no student.
[03/Mar/2019 23:00:40] ERROR [django.server:154] "GET /home/profile/2 HTTP/1.1" 500 73606
[03/Mar/2019 23:09:18] ERROR [django.request:228] Internal Server Error: /home/profile/2
Traceback (most recent call last):
  File "/Library/Frameworks/Python.framework/Versions/3.6/lib/python3.6/site-packages/django/core/handlers/exception.py", line 34, in inner
    response = get_response(request)
  File "/Library/Frameworks/Python.framework/Versions/3.6/lib/python3.6/site-packages/django/core/handlers/base.py", line 126, in _get_response
    response = self.process_exception_by_middleware(e, request)
  File "/Library/Frameworks/Python.framework/Versions/3.6/lib/python3.6/site-packages/django/core/handlers/base.py", line 124, in _get_response
    response = wrapped_callback(request, *callback_args, **callback_kwargs)
  File "/Library/Frameworks/Python.framework/Versions/3.6/lib/python3.6/site-packages/django/contrib/auth/decorators.py", line 21, in _wrapped_view
    return view_func(request, *args, **kwargs)
  File "/Users/islab/Desktop/MusicApp/musicapp/musicapp_project3/home/views.py", line 90, in profile
    if user.student:
  File "/Library/Frameworks/Python.framework/Versions/3.6/lib/python3.6/site-packages/django/db/models/fields/related_descriptors.py", line 414, in __get__
    self.related.get_accessor_name()
django.contrib.auth.models.User.student.RelatedObjectDoesNotExist: User has no student.
[03/Mar/2019 23:09:18] ERROR [django.server:154] "GET /home/profile/2 HTTP/1.1" 500 72926
[03/Mar/2019 23:10:52] ERROR [django.request:228] Internal Server Error: /home/profile/2
Traceback (most recent call last):
  File "/Library/Frameworks/Python.framework/Versions/3.6/lib/python3.6/site-packages/django/core/handlers/exception.py", line 34, in inner
    response = get_response(request)
  File "/Library/Frameworks/Python.framework/Versions/3.6/lib/python3.6/site-packages/django/core/handlers/base.py", line 126, in _get_response
    response = self.process_exception_by_middleware(e, request)
  File "/Library/Frameworks/Python.framework/Versions/3.6/lib/python3.6/site-packages/django/core/handlers/base.py", line 124, in _get_response
    response = wrapped_callback(request, *callback_args, **callback_kwargs)
  File "/Library/Frameworks/Python.framework/Versions/3.6/lib/python3.6/site-packages/django/contrib/auth/decorators.py", line 21, in _wrapped_view
    return view_func(request, *args, **kwargs)
  File "/Users/islab/Desktop/MusicApp/musicapp/musicapp_project3/home/views.py", line 90, in profile
    if user.student:
  File "/Library/Frameworks/Python.framework/Versions/3.6/lib/python3.6/site-packages/django/db/models/fields/related_descriptors.py", line 414, in __get__
    self.related.get_accessor_name()
django.contrib.auth.models.User.student.RelatedObjectDoesNotExist: User has no student.
[03/Mar/2019 23:10:52] ERROR [django.server:154] "GET /home/profile/2 HTTP/1.1" 500 72914
[03/Mar/2019 23:10:55] ERROR [django.request:228] Internal Server Error: /home/profile/2
Traceback (most recent call last):
  File "/Library/Frameworks/Python.framework/Versions/3.6/lib/python3.6/site-packages/django/core/handlers/exception.py", line 34, in inner
    response = get_response(request)
  File "/Library/Frameworks/Python.framework/Versions/3.6/lib/python3.6/site-packages/django/core/handlers/base.py", line 126, in _get_response
    response = self.process_exception_by_middleware(e, request)
  File "/Library/Frameworks/Python.framework/Versions/3.6/lib/python3.6/site-packages/django/core/handlers/base.py", line 124, in _get_response
    response = wrapped_callback(request, *callback_args, **callback_kwargs)
  File "/Library/Frameworks/Python.framework/Versions/3.6/lib/python3.6/site-packages/django/contrib/auth/decorators.py", line 21, in _wrapped_view
    return view_func(request, *args, **kwargs)
  File "/Users/islab/Desktop/MusicApp/musicapp/musicapp_project3/home/views.py", line 90, in profile
    if user.student:
  File "/Library/Frameworks/Python.framework/Versions/3.6/lib/python3.6/site-packages/django/db/models/fields/related_descriptors.py", line 414, in __get__
    self.related.get_accessor_name()
django.contrib.auth.models.User.student.RelatedObjectDoesNotExist: User has no student.
[03/Mar/2019 23:10:55] ERROR [django.server:154] "GET /home/profile/2 HTTP/1.1" 500 72926
[03/Mar/2019 23:11:13] ERROR [django.request:228] Internal Server Error: /home/profile/2
Traceback (most recent call last):
  File "/Library/Frameworks/Python.framework/Versions/3.6/lib/python3.6/site-packages/django/core/handlers/exception.py", line 34, in inner
    response = get_response(request)
  File "/Library/Frameworks/Python.framework/Versions/3.6/lib/python3.6/site-packages/django/core/handlers/base.py", line 126, in _get_response
    response = self.process_exception_by_middleware(e, request)
  File "/Library/Frameworks/Python.framework/Versions/3.6/lib/python3.6/site-packages/django/core/handlers/base.py", line 124, in _get_response
    response = wrapped_callback(request, *callback_args, **callback_kwargs)
  File "/Library/Frameworks/Python.framework/Versions/3.6/lib/python3.6/site-packages/django/contrib/auth/decorators.py", line 21, in _wrapped_view
    return view_func(request, *args, **kwargs)
  File "/Users/islab/Desktop/MusicApp/musicapp/musicapp_project3/home/views.py", line 90, in profile
    if user.student == True:
  File "/Library/Frameworks/Python.framework/Versions/3.6/lib/python3.6/site-packages/django/db/models/fields/related_descriptors.py", line 414, in __get__
    self.related.get_accessor_name()
django.contrib.auth.models.User.student.RelatedObjectDoesNotExist: User has no student.
[03/Mar/2019 23:11:13] ERROR [django.server:154] "GET /home/profile/2 HTTP/1.1" 500 72930
[03/Mar/2019 23:11:15] ERROR [django.request:228] Internal Server Error: /home/profile/2
Traceback (most recent call last):
  File "/Library/Frameworks/Python.framework/Versions/3.6/lib/python3.6/site-packages/django/core/handlers/exception.py", line 34, in inner
    response = get_response(request)
  File "/Library/Frameworks/Python.framework/Versions/3.6/lib/python3.6/site-packages/django/core/handlers/base.py", line 126, in _get_response
    response = self.process_exception_by_middleware(e, request)
  File "/Library/Frameworks/Python.framework/Versions/3.6/lib/python3.6/site-packages/django/core/handlers/base.py", line 124, in _get_response
    response = wrapped_callback(request, *callback_args, **callback_kwargs)
  File "/Library/Frameworks/Python.framework/Versions/3.6/lib/python3.6/site-packages/django/contrib/auth/decorators.py", line 21, in _wrapped_view
    return view_func(request, *args, **kwargs)
  File "/Users/islab/Desktop/MusicApp/musicapp/musicapp_project3/home/views.py", line 90, in profile
    if user.student == True:
  File "/Library/Frameworks/Python.framework/Versions/3.6/lib/python3.6/site-packages/django/db/models/fields/related_descriptors.py", line 414, in __get__
    self.related.get_accessor_name()
django.contrib.auth.models.User.student.RelatedObjectDoesNotExist: User has no student.
[03/Mar/2019 23:11:15] ERROR [django.server:154] "GET /home/profile/2 HTTP/1.1" 500 72942
[03/Mar/2019 23:12:09] ERROR [django.request:228] Internal Server Error: /home/profile/2
Traceback (most recent call last):
  File "/Library/Frameworks/Python.framework/Versions/3.6/lib/python3.6/site-packages/django/core/handlers/exception.py", line 34, in inner
    response = get_response(request)
  File "/Library/Frameworks/Python.framework/Versions/3.6/lib/python3.6/site-packages/django/core/handlers/base.py", line 126, in _get_response
    response = self.process_exception_by_middleware(e, request)
  File "/Library/Frameworks/Python.framework/Versions/3.6/lib/python3.6/site-packages/django/core/handlers/base.py", line 124, in _get_response
    response = wrapped_callback(request, *callback_args, **callback_kwargs)
  File "/Library/Frameworks/Python.framework/Versions/3.6/lib/python3.6/site-packages/django/contrib/auth/decorators.py", line 21, in _wrapped_view
    return view_func(request, *args, **kwargs)
  File "/Users/islab/Desktop/MusicApp/musicapp/musicapp_project3/home/views.py", line 90, in profile
    if request.user.student:
  File "/Library/Frameworks/Python.framework/Versions/3.6/lib/python3.6/site-packages/django/utils/functional.py", line 214, in inner
    return func(self._wrapped, *args)
  File "/Library/Frameworks/Python.framework/Versions/3.6/lib/python3.6/site-packages/django/db/models/fields/related_descriptors.py", line 414, in __get__
    self.related.get_accessor_name()
django.contrib.auth.models.User.student.RelatedObjectDoesNotExist: User has no student.
[03/Mar/2019 23:12:09] ERROR [django.server:154] "GET /home/profile/2 HTTP/1.1" 500 76659
[03/Mar/2019 23:12:14] ERROR [django.request:228] Internal Server Error: /home/profile/2
Traceback (most recent call last):
  File "/Library/Frameworks/Python.framework/Versions/3.6/lib/python3.6/site-packages/django/core/handlers/exception.py", line 34, in inner
    response = get_response(request)
  File "/Library/Frameworks/Python.framework/Versions/3.6/lib/python3.6/site-packages/django/core/handlers/base.py", line 126, in _get_response
    response = self.process_exception_by_middleware(e, request)
  File "/Library/Frameworks/Python.framework/Versions/3.6/lib/python3.6/site-packages/django/core/handlers/base.py", line 124, in _get_response
    response = wrapped_callback(request, *callback_args, **callback_kwargs)
  File "/Library/Frameworks/Python.framework/Versions/3.6/lib/python3.6/site-packages/django/contrib/auth/decorators.py", line 21, in _wrapped_view
    return view_func(request, *args, **kwargs)
  File "/Users/islab/Desktop/MusicApp/musicapp/musicapp_project3/home/views.py", line 90, in profile
    if request.user.student:
  File "/Library/Frameworks/Python.framework/Versions/3.6/lib/python3.6/site-packages/django/utils/functional.py", line 214, in inner
    return func(self._wrapped, *args)
  File "/Library/Frameworks/Python.framework/Versions/3.6/lib/python3.6/site-packages/django/db/models/fields/related_descriptors.py", line 414, in __get__
    self.related.get_accessor_name()
django.contrib.auth.models.User.student.RelatedObjectDoesNotExist: User has no student.
[03/Mar/2019 23:12:14] ERROR [django.server:154] "GET /home/profile/2 HTTP/1.1" 500 76671
[03/Mar/2019 23:12:31] ERROR [django.request:228] Internal Server Error: /home/profile/2
Traceback (most recent call last):
  File "/Library/Frameworks/Python.framework/Versions/3.6/lib/python3.6/site-packages/django/core/handlers/exception.py", line 34, in inner
    response = get_response(request)
  File "/Library/Frameworks/Python.framework/Versions/3.6/lib/python3.6/site-packages/django/core/handlers/base.py", line 126, in _get_response
    response = self.process_exception_by_middleware(e, request)
  File "/Library/Frameworks/Python.framework/Versions/3.6/lib/python3.6/site-packages/django/core/handlers/base.py", line 124, in _get_response
    response = wrapped_callback(request, *callback_args, **callback_kwargs)
  File "/Library/Frameworks/Python.framework/Versions/3.6/lib/python3.6/site-packages/django/contrib/auth/decorators.py", line 21, in _wrapped_view
    return view_func(request, *args, **kwargs)
  File "/Users/islab/Desktop/MusicApp/musicapp/musicapp_project3/home/views.py", line 95, in profile
    if(book.student == user.student):
  File "/Library/Frameworks/Python.framework/Versions/3.6/lib/python3.6/site-packages/django/db/models/fields/related_descriptors.py", line 414, in __get__
    self.related.get_accessor_name()
django.contrib.auth.models.User.student.RelatedObjectDoesNotExist: User has no student.
[03/Mar/2019 23:12:31] ERROR [django.server:154] "GET /home/profile/2 HTTP/1.1" 500 73659
[03/Mar/2019 23:12:51] ERROR [django.request:228] Internal Server Error: /home/profile/2
Traceback (most recent call last):
  File "/Library/Frameworks/Python.framework/Versions/3.6/lib/python3.6/site-packages/django/core/handlers/exception.py", line 34, in inner
    response = get_response(request)
  File "/Library/Frameworks/Python.framework/Versions/3.6/lib/python3.6/site-packages/django/core/handlers/base.py", line 126, in _get_response
    response = self.process_exception_by_middleware(e, request)
  File "/Library/Frameworks/Python.framework/Versions/3.6/lib/python3.6/site-packages/django/core/handlers/base.py", line 124, in _get_response
    response = wrapped_callback(request, *callback_args, **callback_kwargs)
  File "/Library/Frameworks/Python.framework/Versions/3.6/lib/python3.6/site-packages/django/contrib/auth/decorators.py", line 21, in _wrapped_view
    return view_func(request, *args, **kwargs)
  File "/Users/islab/Desktop/MusicApp/musicapp/musicapp_project3/home/views.py", line 90, in profile
    if request.user.student:
  File "/Library/Frameworks/Python.framework/Versions/3.6/lib/python3.6/site-packages/django/utils/functional.py", line 214, in inner
    return func(self._wrapped, *args)
  File "/Library/Frameworks/Python.framework/Versions/3.6/lib/python3.6/site-packages/django/db/models/fields/related_descriptors.py", line 414, in __get__
    self.related.get_accessor_name()
django.contrib.auth.models.User.student.RelatedObjectDoesNotExist: User has no student.
[03/Mar/2019 23:12:51] ERROR [django.server:154] "GET /home/profile/2 HTTP/1.1" 500 76659
[03/Mar/2019 23:12:54] ERROR [django.request:228] Internal Server Error: /home/profile/2
Traceback (most recent call last):
  File "/Library/Frameworks/Python.framework/Versions/3.6/lib/python3.6/site-packages/django/core/handlers/exception.py", line 34, in inner
    response = get_response(request)
  File "/Library/Frameworks/Python.framework/Versions/3.6/lib/python3.6/site-packages/django/core/handlers/base.py", line 126, in _get_response
    response = self.process_exception_by_middleware(e, request)
  File "/Library/Frameworks/Python.framework/Versions/3.6/lib/python3.6/site-packages/django/core/handlers/base.py", line 124, in _get_response
    response = wrapped_callback(request, *callback_args, **callback_kwargs)
  File "/Library/Frameworks/Python.framework/Versions/3.6/lib/python3.6/site-packages/django/contrib/auth/decorators.py", line 21, in _wrapped_view
    return view_func(request, *args, **kwargs)
  File "/Users/islab/Desktop/MusicApp/musicapp/musicapp_project3/home/views.py", line 90, in profile
    if request.user.student:
  File "/Library/Frameworks/Python.framework/Versions/3.6/lib/python3.6/site-packages/django/utils/functional.py", line 214, in inner
    return func(self._wrapped, *args)
  File "/Library/Frameworks/Python.framework/Versions/3.6/lib/python3.6/site-packages/django/db/models/fields/related_descriptors.py", line 414, in __get__
    self.related.get_accessor_name()
django.contrib.auth.models.User.student.RelatedObjectDoesNotExist: User has no student.
[03/Mar/2019 23:12:54] ERROR [django.server:154] "GET /home/profile/2 HTTP/1.1" 500 76671
[03/Mar/2019 23:18:51] INFO [home.views:22] User: Casey logged in
[03/Mar/2019 23:18:53] ERROR [django.request:228] Internal Server Error: /home/profile/3
Traceback (most recent call last):
  File "/Library/Frameworks/Python.framework/Versions/3.6/lib/python3.6/site-packages/django/core/handlers/exception.py", line 34, in inner
    response = get_response(request)
  File "/Library/Frameworks/Python.framework/Versions/3.6/lib/python3.6/site-packages/django/core/handlers/base.py", line 126, in _get_response
    response = self.process_exception_by_middleware(e, request)
  File "/Library/Frameworks/Python.framework/Versions/3.6/lib/python3.6/site-packages/django/core/handlers/base.py", line 124, in _get_response
    response = wrapped_callback(request, *callback_args, **callback_kwargs)
  File "/Library/Frameworks/Python.framework/Versions/3.6/lib/python3.6/site-packages/django/contrib/auth/decorators.py", line 21, in _wrapped_view
    return view_func(request, *args, **kwargs)
  File "/Users/islab/Desktop/MusicApp/musicapp/musicapp_project3/home/views.py", line 101, in profile
    if request.user.tutor:
  File "/Library/Frameworks/Python.framework/Versions/3.6/lib/python3.6/site-packages/django/utils/functional.py", line 214, in inner
    return func(self._wrapped, *args)
  File "/Library/Frameworks/Python.framework/Versions/3.6/lib/python3.6/site-packages/django/db/models/fields/related_descriptors.py", line 414, in __get__
    self.related.get_accessor_name()
django.contrib.auth.models.User.tutor.RelatedObjectDoesNotExist: User has no tutor.
[03/Mar/2019 23:18:53] ERROR [django.server:154] "GET /home/profile/3 HTTP/1.1" 500 76666
[03/Mar/2019 23:19:15] ERROR [django.request:228] Internal Server Error: /home/profile/3
Traceback (most recent call last):
  File "/Library/Frameworks/Python.framework/Versions/3.6/lib/python3.6/site-packages/django/core/handlers/exception.py", line 34, in inner
    response = get_response(request)
  File "/Library/Frameworks/Python.framework/Versions/3.6/lib/python3.6/site-packages/django/core/handlers/base.py", line 126, in _get_response
    response = self.process_exception_by_middleware(e, request)
  File "/Library/Frameworks/Python.framework/Versions/3.6/lib/python3.6/site-packages/django/core/handlers/base.py", line 124, in _get_response
    response = wrapped_callback(request, *callback_args, **callback_kwargs)
  File "/Library/Frameworks/Python.framework/Versions/3.6/lib/python3.6/site-packages/django/contrib/auth/decorators.py", line 21, in _wrapped_view
    return view_func(request, *args, **kwargs)
  File "/Users/islab/Desktop/MusicApp/musicapp/musicapp_project3/home/views.py", line 101, in profile
    if request.user.tutor:
  File "/Library/Frameworks/Python.framework/Versions/3.6/lib/python3.6/site-packages/django/utils/functional.py", line 214, in inner
    return func(self._wrapped, *args)
  File "/Library/Frameworks/Python.framework/Versions/3.6/lib/python3.6/site-packages/django/db/models/fields/related_descriptors.py", line 414, in __get__
    self.related.get_accessor_name()
django.contrib.auth.models.User.tutor.RelatedObjectDoesNotExist: User has no tutor.
[03/Mar/2019 23:19:15] ERROR [django.server:154] "GET /home/profile/3 HTTP/1.1" 500 76675
[03/Mar/2019 23:19:17] ERROR [django.request:228] Internal Server Error: /home/profile/3
Traceback (most recent call last):
  File "/Library/Frameworks/Python.framework/Versions/3.6/lib/python3.6/site-packages/django/core/handlers/exception.py", line 34, in inner
    response = get_response(request)
  File "/Library/Frameworks/Python.framework/Versions/3.6/lib/python3.6/site-packages/django/core/handlers/base.py", line 126, in _get_response
    response = self.process_exception_by_middleware(e, request)
  File "/Library/Frameworks/Python.framework/Versions/3.6/lib/python3.6/site-packages/django/core/handlers/base.py", line 124, in _get_response
    response = wrapped_callback(request, *callback_args, **callback_kwargs)
  File "/Library/Frameworks/Python.framework/Versions/3.6/lib/python3.6/site-packages/django/contrib/auth/decorators.py", line 21, in _wrapped_view
    return view_func(request, *args, **kwargs)
  File "/Users/islab/Desktop/MusicApp/musicapp/musicapp_project3/home/views.py", line 101, in profile
    if request.user.tutor:
  File "/Library/Frameworks/Python.framework/Versions/3.6/lib/python3.6/site-packages/django/utils/functional.py", line 214, in inner
    return func(self._wrapped, *args)
  File "/Library/Frameworks/Python.framework/Versions/3.6/lib/python3.6/site-packages/django/db/models/fields/related_descriptors.py", line 414, in __get__
    self.related.get_accessor_name()
django.contrib.auth.models.User.tutor.RelatedObjectDoesNotExist: User has no tutor.
[03/Mar/2019 23:19:17] ERROR [django.server:154] "GET /home/profile/3 HTTP/1.1" 500 76687
[03/Mar/2019 23:20:27] ERROR [django.request:228] Internal Server Error: /home/profile/3
Traceback (most recent call last):
  File "/Library/Frameworks/Python.framework/Versions/3.6/lib/python3.6/site-packages/django/core/handlers/exception.py", line 34, in inner
    response = get_response(request)
  File "/Library/Frameworks/Python.framework/Versions/3.6/lib/python3.6/site-packages/django/core/handlers/base.py", line 126, in _get_response
    response = self.process_exception_by_middleware(e, request)
  File "/Library/Frameworks/Python.framework/Versions/3.6/lib/python3.6/site-packages/django/core/handlers/base.py", line 124, in _get_response
    response = wrapped_callback(request, *callback_args, **callback_kwargs)
  File "/Library/Frameworks/Python.framework/Versions/3.6/lib/python3.6/site-packages/django/contrib/auth/decorators.py", line 21, in _wrapped_view
    return view_func(request, *args, **kwargs)
  File "/Users/islab/Desktop/MusicApp/musicapp/musicapp_project3/home/views.py", line 101, in profile
    if request.user.tutor:
  File "/Library/Frameworks/Python.framework/Versions/3.6/lib/python3.6/site-packages/django/utils/functional.py", line 214, in inner
    return func(self._wrapped, *args)
  File "/Library/Frameworks/Python.framework/Versions/3.6/lib/python3.6/site-packages/django/db/models/fields/related_descriptors.py", line 414, in __get__
    self.related.get_accessor_name()
django.contrib.auth.models.User.tutor.RelatedObjectDoesNotExist: User has no tutor.
[03/Mar/2019 23:20:27] ERROR [django.server:154] "GET /home/profile/3 HTTP/1.1" 500 76627
[03/Mar/2019 23:20:29] ERROR [django.request:228] Internal Server Error: /home/profile/3
Traceback (most recent call last):
  File "/Library/Frameworks/Python.framework/Versions/3.6/lib/python3.6/site-packages/django/core/handlers/exception.py", line 34, in inner
    response = get_response(request)
  File "/Library/Frameworks/Python.framework/Versions/3.6/lib/python3.6/site-packages/django/core/handlers/base.py", line 126, in _get_response
    response = self.process_exception_by_middleware(e, request)
  File "/Library/Frameworks/Python.framework/Versions/3.6/lib/python3.6/site-packages/django/core/handlers/base.py", line 124, in _get_response
    response = wrapped_callback(request, *callback_args, **callback_kwargs)
  File "/Library/Frameworks/Python.framework/Versions/3.6/lib/python3.6/site-packages/django/contrib/auth/decorators.py", line 21, in _wrapped_view
    return view_func(request, *args, **kwargs)
  File "/Users/islab/Desktop/MusicApp/musicapp/musicapp_project3/home/views.py", line 101, in profile
    if request.user.tutor:
  File "/Library/Frameworks/Python.framework/Versions/3.6/lib/python3.6/site-packages/django/utils/functional.py", line 214, in inner
    return func(self._wrapped, *args)
  File "/Library/Frameworks/Python.framework/Versions/3.6/lib/python3.6/site-packages/django/db/models/fields/related_descriptors.py", line 414, in __get__
    self.related.get_accessor_name()
django.contrib.auth.models.User.tutor.RelatedObjectDoesNotExist: User has no tutor.
[03/Mar/2019 23:20:29] ERROR [django.server:154] "GET /home/profile/3 HTTP/1.1" 500 76639
[03/Mar/2019 23:23:18] INFO [home.views:22] User: Mike logged in
[03/Mar/2019 23:23:20] ERROR [django.request:228] Internal Server Error: /home/profile/2
Traceback (most recent call last):
  File "/Library/Frameworks/Python.framework/Versions/3.6/lib/python3.6/site-packages/django/core/handlers/exception.py", line 34, in inner
    response = get_response(request)
  File "/Library/Frameworks/Python.framework/Versions/3.6/lib/python3.6/site-packages/django/core/handlers/base.py", line 126, in _get_response
    response = self.process_exception_by_middleware(e, request)
  File "/Library/Frameworks/Python.framework/Versions/3.6/lib/python3.6/site-packages/django/core/handlers/base.py", line 124, in _get_response
    response = wrapped_callback(request, *callback_args, **callback_kwargs)
  File "/Library/Frameworks/Python.framework/Versions/3.6/lib/python3.6/site-packages/django/contrib/auth/decorators.py", line 21, in _wrapped_view
    return view_func(request, *args, **kwargs)
  File "/Users/islab/Desktop/MusicApp/musicapp/musicapp_project3/home/views.py", line 106, in profile
    if(book.student == user.student):
  File "/Library/Frameworks/Python.framework/Versions/3.6/lib/python3.6/site-packages/django/db/models/fields/related_descriptors.py", line 414, in __get__
    self.related.get_accessor_name()
django.contrib.auth.models.User.student.RelatedObjectDoesNotExist: User has no student.
[03/Mar/2019 23:23:20] ERROR [django.server:154] "GET /home/profile/2 HTTP/1.1" 500 73542
[03/Mar/2019 23:24:48] ERROR [django.request:228] Internal Server Error: /home/profile/2
Traceback (most recent call last):
  File "/Library/Frameworks/Python.framework/Versions/3.6/lib/python3.6/site-packages/django/core/handlers/exception.py", line 34, in inner
    response = get_response(request)
  File "/Library/Frameworks/Python.framework/Versions/3.6/lib/python3.6/site-packages/django/core/handlers/base.py", line 126, in _get_response
    response = self.process_exception_by_middleware(e, request)
  File "/Library/Frameworks/Python.framework/Versions/3.6/lib/python3.6/site-packages/django/core/handlers/base.py", line 124, in _get_response
    response = wrapped_callback(request, *callback_args, **callback_kwargs)
  File "/Library/Frameworks/Python.framework/Versions/3.6/lib/python3.6/site-packages/django/contrib/auth/decorators.py", line 21, in _wrapped_view
    return view_func(request, *args, **kwargs)
  File "/Users/islab/Desktop/MusicApp/musicapp/musicapp_project3/home/views.py", line 101, in profile
    if request.user.student:
  File "/Library/Frameworks/Python.framework/Versions/3.6/lib/python3.6/site-packages/django/utils/functional.py", line 214, in inner
    return func(self._wrapped, *args)
  File "/Library/Frameworks/Python.framework/Versions/3.6/lib/python3.6/site-packages/django/db/models/fields/related_descriptors.py", line 414, in __get__
    self.related.get_accessor_name()
django.contrib.auth.models.User.student.RelatedObjectDoesNotExist: User has no student.
[03/Mar/2019 23:24:48] ERROR [django.server:154] "GET /home/profile/2 HTTP/1.1" 500 76665
[03/Mar/2019 23:25:04] ERROR [django.request:228] Internal Server Error: /home/profile/2
Traceback (most recent call last):
  File "/Library/Frameworks/Python.framework/Versions/3.6/lib/python3.6/site-packages/django/core/handlers/exception.py", line 34, in inner
    response = get_response(request)
  File "/Library/Frameworks/Python.framework/Versions/3.6/lib/python3.6/site-packages/django/core/handlers/base.py", line 126, in _get_response
    response = self.process_exception_by_middleware(e, request)
  File "/Library/Frameworks/Python.framework/Versions/3.6/lib/python3.6/site-packages/django/core/handlers/base.py", line 124, in _get_response
    response = wrapped_callback(request, *callback_args, **callback_kwargs)
  File "/Library/Frameworks/Python.framework/Versions/3.6/lib/python3.6/site-packages/django/contrib/auth/decorators.py", line 21, in _wrapped_view
    return view_func(request, *args, **kwargs)
  File "/Users/islab/Desktop/MusicApp/musicapp/musicapp_project3/home/views.py", line 101, in profile
    if request.user.student:
  File "/Library/Frameworks/Python.framework/Versions/3.6/lib/python3.6/site-packages/django/utils/functional.py", line 214, in inner
    return func(self._wrapped, *args)
  File "/Library/Frameworks/Python.framework/Versions/3.6/lib/python3.6/site-packages/django/db/models/fields/related_descriptors.py", line 414, in __get__
    self.related.get_accessor_name()
django.contrib.auth.models.User.student.RelatedObjectDoesNotExist: User has no student.
[03/Mar/2019 23:25:04] ERROR [django.server:154] "GET /home/profile/2 HTTP/1.1" 500 76665
[03/Mar/2019 23:25:05] ERROR [django.request:228] Internal Server Error: /home/profile/2
Traceback (most recent call last):
  File "/Library/Frameworks/Python.framework/Versions/3.6/lib/python3.6/site-packages/django/core/handlers/exception.py", line 34, in inner
    response = get_response(request)
  File "/Library/Frameworks/Python.framework/Versions/3.6/lib/python3.6/site-packages/django/core/handlers/base.py", line 126, in _get_response
    response = self.process_exception_by_middleware(e, request)
  File "/Library/Frameworks/Python.framework/Versions/3.6/lib/python3.6/site-packages/django/core/handlers/base.py", line 124, in _get_response
    response = wrapped_callback(request, *callback_args, **callback_kwargs)
  File "/Library/Frameworks/Python.framework/Versions/3.6/lib/python3.6/site-packages/django/contrib/auth/decorators.py", line 21, in _wrapped_view
    return view_func(request, *args, **kwargs)
  File "/Users/islab/Desktop/MusicApp/musicapp/musicapp_project3/home/views.py", line 101, in profile
    if request.user.student:
  File "/Library/Frameworks/Python.framework/Versions/3.6/lib/python3.6/site-packages/django/utils/functional.py", line 214, in inner
    return func(self._wrapped, *args)
  File "/Library/Frameworks/Python.framework/Versions/3.6/lib/python3.6/site-packages/django/db/models/fields/related_descriptors.py", line 414, in __get__
    self.related.get_accessor_name()
django.contrib.auth.models.User.student.RelatedObjectDoesNotExist: User has no student.
[03/Mar/2019 23:25:05] ERROR [django.server:154] "GET /home/profile/2 HTTP/1.1" 500 76665
[03/Mar/2019 23:30:08] ERROR [django.request:228] Internal Server Error: /home/profile/2
Traceback (most recent call last):
  File "/Library/Frameworks/Python.framework/Versions/3.6/lib/python3.6/site-packages/django/core/handlers/exception.py", line 34, in inner
    response = get_response(request)
  File "/Library/Frameworks/Python.framework/Versions/3.6/lib/python3.6/site-packages/django/core/handlers/base.py", line 126, in _get_response
    response = self.process_exception_by_middleware(e, request)
  File "/Library/Frameworks/Python.framework/Versions/3.6/lib/python3.6/site-packages/django/core/handlers/base.py", line 124, in _get_response
    response = wrapped_callback(request, *callback_args, **callback_kwargs)
  File "/Library/Frameworks/Python.framework/Versions/3.6/lib/python3.6/site-packages/django/contrib/auth/decorators.py", line 21, in _wrapped_view
    return view_func(request, *args, **kwargs)
  File "/Users/islab/Desktop/MusicApp/musicapp/musicapp_project3/home/views.py", line 114, in profile
    return render(request, 'home/profile.html', {'user': user, 'userBookings': userBookings, 'bookings': bookings})
NameError: name 'user' is not defined
[03/Mar/2019 23:30:08] ERROR [django.server:154] "GET /home/profile/2 HTTP/1.1" 500 68825
[03/Mar/2019 23:30:40] ERROR [django.request:228] Internal Server Error: /home/profile/2
Traceback (most recent call last):
  File "/Library/Frameworks/Python.framework/Versions/3.6/lib/python3.6/site-packages/django/core/handlers/exception.py", line 34, in inner
    response = get_response(request)
  File "/Library/Frameworks/Python.framework/Versions/3.6/lib/python3.6/site-packages/django/core/handlers/base.py", line 126, in _get_response
    response = self.process_exception_by_middleware(e, request)
  File "/Library/Frameworks/Python.framework/Versions/3.6/lib/python3.6/site-packages/django/core/handlers/base.py", line 124, in _get_response
    response = wrapped_callback(request, *callback_args, **callback_kwargs)
  File "/Library/Frameworks/Python.framework/Versions/3.6/lib/python3.6/site-packages/django/contrib/auth/decorators.py", line 21, in _wrapped_view
    return view_func(request, *args, **kwargs)
  File "/Users/islab/Desktop/MusicApp/musicapp/musicapp_project3/home/views.py", line 113, in profile
    return render(request, 'home/profile.html', {'user': user, 'userBookings': userBookings, 'bookings': bookings})
NameError: name 'userBookings' is not defined
[03/Mar/2019 23:30:40] ERROR [django.server:154] "GET /home/profile/2 HTTP/1.1" 500 68790
[03/Mar/2019 23:31:09] ERROR [django.request:228] Internal Server Error: /home/profile/2
Traceback (most recent call last):
  File "/Library/Frameworks/Python.framework/Versions/3.6/lib/python3.6/site-packages/django/core/handlers/exception.py", line 34, in inner
    response = get_response(request)
  File "/Library/Frameworks/Python.framework/Versions/3.6/lib/python3.6/site-packages/django/core/handlers/base.py", line 126, in _get_response
    response = self.process_exception_by_middleware(e, request)
  File "/Library/Frameworks/Python.framework/Versions/3.6/lib/python3.6/site-packages/django/core/handlers/base.py", line 124, in _get_response
    response = wrapped_callback(request, *callback_args, **callback_kwargs)
  File "/Library/Frameworks/Python.framework/Versions/3.6/lib/python3.6/site-packages/django/contrib/auth/decorators.py", line 21, in _wrapped_view
    return view_func(request, *args, **kwargs)
  File "/Users/islab/Desktop/MusicApp/musicapp/musicapp_project3/home/views.py", line 112, in profile
    return render(request, 'home/profile.html', {'user': user, 'userBookings': userBookings, 'bookings': bookings})
NameError: name 'user' is not defined
[03/Mar/2019 23:31:09] ERROR [django.server:154] "GET /home/profile/2 HTTP/1.1" 500 68577
[03/Mar/2019 23:31:43] ERROR [django.request:228] Internal Server Error: /home/profile/2
Traceback (most recent call last):
  File "/Library/Frameworks/Python.framework/Versions/3.6/lib/python3.6/site-packages/django/core/handlers/exception.py", line 34, in inner
    response = get_response(request)
  File "/Library/Frameworks/Python.framework/Versions/3.6/lib/python3.6/site-packages/django/core/handlers/base.py", line 126, in _get_response
    response = self.process_exception_by_middleware(e, request)
  File "/Library/Frameworks/Python.framework/Versions/3.6/lib/python3.6/site-packages/django/core/handlers/base.py", line 124, in _get_response
    response = wrapped_callback(request, *callback_args, **callback_kwargs)
  File "/Library/Frameworks/Python.framework/Versions/3.6/lib/python3.6/site-packages/django/contrib/auth/decorators.py", line 21, in _wrapped_view
    return view_func(request, *args, **kwargs)
  File "/Users/islab/Desktop/MusicApp/musicapp/musicapp_project3/home/views.py", line 112, in profile
    return render(request, 'home/profile.html', {'user': user, 'userBookings': userBookings, 'bookings': bookings})
NameError: name 'user' is not defined
[03/Mar/2019 23:31:43] ERROR [django.server:154] "GET /home/profile/2 HTTP/1.1" 500 68648
[03/Mar/2019 23:33:08] ERROR [django.request:228] Internal Server Error: /home/profile/2
Traceback (most recent call last):
  File "/Library/Frameworks/Python.framework/Versions/3.6/lib/python3.6/site-packages/django/core/handlers/exception.py", line 34, in inner
    response = get_response(request)
  File "/Library/Frameworks/Python.framework/Versions/3.6/lib/python3.6/site-packages/django/core/handlers/base.py", line 126, in _get_response
    response = self.process_exception_by_middleware(e, request)
  File "/Library/Frameworks/Python.framework/Versions/3.6/lib/python3.6/site-packages/django/core/handlers/base.py", line 124, in _get_response
    response = wrapped_callback(request, *callback_args, **callback_kwargs)
  File "/Library/Frameworks/Python.framework/Versions/3.6/lib/python3.6/site-packages/django/contrib/auth/decorators.py", line 21, in _wrapped_view
    return view_func(request, *args, **kwargs)
  File "/Users/islab/Desktop/MusicApp/musicapp/musicapp_project3/home/views.py", line 117, in profile
    return render(request, 'home/profile.html', {'user': user, 'userBookings': userBookings, 'bookings': bookings})
NameError: name 'userBookings' is not defined
[03/Mar/2019 23:33:08] ERROR [django.server:154] "GET /home/profile/2 HTTP/1.1" 500 68990
[03/Mar/2019 23:33:58] INFO [home.views:22] User: Casey logged in
[03/Mar/2019 23:33:59] ERROR [django.request:228] Internal Server Error: /home/profile/3
Traceback (most recent call last):
  File "/Library/Frameworks/Python.framework/Versions/3.6/lib/python3.6/site-packages/django/core/handlers/exception.py", line 34, in inner
    response = get_response(request)
  File "/Library/Frameworks/Python.framework/Versions/3.6/lib/python3.6/site-packages/django/core/handlers/base.py", line 126, in _get_response
    response = self.process_exception_by_middleware(e, request)
  File "/Library/Frameworks/Python.framework/Versions/3.6/lib/python3.6/site-packages/django/core/handlers/base.py", line 124, in _get_response
    response = wrapped_callback(request, *callback_args, **callback_kwargs)
  File "/Library/Frameworks/Python.framework/Versions/3.6/lib/python3.6/site-packages/django/contrib/auth/decorators.py", line 21, in _wrapped_view
    return view_func(request, *args, **kwargs)
  File "/Users/islab/Desktop/MusicApp/musicapp/musicapp_project3/home/views.py", line 117, in profile
    return render(request, 'home/profile.html', {'user': user, 'userBookings': userBookings, 'bookings': bookings})
NameError: name 'userBookings' is not defined
[03/Mar/2019 23:33:59] ERROR [django.server:154] "GET /home/profile/3 HTTP/1.1" 500 68992
[03/Mar/2019 23:34:03] ERROR [django.request:228] Internal Server Error: /home/profile/3
Traceback (most recent call last):
  File "/Library/Frameworks/Python.framework/Versions/3.6/lib/python3.6/site-packages/django/core/handlers/exception.py", line 34, in inner
    response = get_response(request)
  File "/Library/Frameworks/Python.framework/Versions/3.6/lib/python3.6/site-packages/django/core/handlers/base.py", line 126, in _get_response
    response = self.process_exception_by_middleware(e, request)
  File "/Library/Frameworks/Python.framework/Versions/3.6/lib/python3.6/site-packages/django/core/handlers/base.py", line 124, in _get_response
    response = wrapped_callback(request, *callback_args, **callback_kwargs)
  File "/Library/Frameworks/Python.framework/Versions/3.6/lib/python3.6/site-packages/django/contrib/auth/decorators.py", line 21, in _wrapped_view
    return view_func(request, *args, **kwargs)
  File "/Users/islab/Desktop/MusicApp/musicapp/musicapp_project3/home/views.py", line 113, in profile
    return render(request, 'home/profile.html', {'user': user, 'userBookings': userBookings, 'bookings': bookings})
NameError: name 'userBookings' is not defined
[03/Mar/2019 23:34:03] ERROR [django.server:154] "GET /home/profile/3 HTTP/1.1" 500 68792
[03/Mar/2019 23:35:12] INFO [home.views:22] User: Mike logged in
